<?xml version="1.0" encoding="UTF-8"?>
<!-- Generated by org.testng.reporters.JUnitXMLReporter -->
<testsuite hostname="ALPA0003.local" name="Command line test" tests="3" failures="2" timestamp="10 Feb 2018 08:58:40 GMT" time="0.033" errors="0">
  <testcase name="testPositiveScenario" time="0.01" classname="com.qait.math.TestngAdd">
    <failure type="java.lang.AssertionError" message="expected [6] but found [5]">
      <![CDATA[java.lang.AssertionError: expected [6] but found [5]
	at com.qait.math.TestngAdd.testPositiveScenario(TestngAdd.java:12)
	at org.apache.maven.surefire.testng.TestNGExecutor.run(TestNGExecutor.java:77)
	at org.apache.maven.surefire.testng.TestNGDirectoryTestSuite.execute(TestNGDirectoryTestSuite.java:110)
	at org.apache.maven.surefire.testng.TestNGProvider.invoke(TestNGProvider.java:106)
	at org.apache.maven.surefire.util.ReflectionUtils.invokeMethodWithArray(ReflectionUtils.java:189)
	at org.apache.maven.surefire.booter.ProviderFactory$ProviderProxy.invoke(ProviderFactory.java:165)
	at org.apache.maven.surefire.booter.ProviderFactory.invokeProvider(ProviderFactory.java:85)
	at org.apache.maven.surefire.booter.ForkedBooter.runSuitesInProcess(ForkedBooter.java:115)
	at org.apache.maven.surefire.booter.ForkedBooter.main(ForkedBooter.java:75)
... Removed 30 stack frames]]>
    </failure>
  </testcase> <!-- testPositiveScenario -->
  <testcase name="testExceptionScenario" time="0.0" classname="com.qait.math.TestngAdd">
    <failure type="org.testng.TestException" message="
Expected exception com.qait.math.InputNotANumberException but got org.testng.TestException: 
Expected exception com.qait.math.InputNotANumberException but got java.lang.AssertionError: expected [6] but found [3]">
      <![CDATA[org.testng.TestException: 
Expected exception com.qait.math.InputNotANumberException but got java.lang.AssertionError: expected [6] but found [3]
	at org.apache.maven.surefire.testng.TestNGExecutor.run(TestNGExecutor.java:77)
	at org.apache.maven.surefire.testng.TestNGDirectoryTestSuite.execute(TestNGDirectoryTestSuite.java:110)
	at org.apache.maven.surefire.testng.TestNGProvider.invoke(TestNGProvider.java:106)
	at org.apache.maven.surefire.util.ReflectionUtils.invokeMethodWithArray(ReflectionUtils.java:189)
	at org.apache.maven.surefire.booter.ProviderFactory$ProviderProxy.invoke(ProviderFactory.java:165)
	at org.apache.maven.surefire.booter.ProviderFactory.invokeProvider(ProviderFactory.java:85)
	at org.apache.maven.surefire.booter.ForkedBooter.runSuitesInProcess(ForkedBooter.java:115)
	at org.apache.maven.surefire.booter.ForkedBooter.main(ForkedBooter.java:75)
Expected exception com.qait.math.InputNotANumberException but got java.lang.AssertionError: expected [6] but found [3]
	... 25 more
Caused by: java.lang.AssertionError: expected [6] but found [3]
	at com.qait.math.TestngAdd.testExceptionScenario(TestngAdd.java:20)
	... 27 more
... Removed 36 stack frames]]>
    </failure>
  </testcase> <!-- testExceptionScenario -->
  <testcase name="testDependency" time="0.001" classname="com.qait.math.TestngAdd">
    <skipped/>
  </testcase> <!-- testDependency -->
</testsuite> <!-- Command line test -->
